<?xml version="1.0"?>
<robot xmlns:xacro="http://www.ros.org/wiki/xacro" name="my_bot">
    <xacro:include filename="inertial_macros.xacro"/>
    <xacro:include filename="gazebo_control.xacro"/>

    <!-- Define materials for the robot -->
    <material name="blue">
        <color rgba="0 0 1 1"/>
    </material>
    <material name="black">
        <color rgba="0 0 0 1"/>
    </material>
    <material name="white">
        <color rgba="1 1 1 1"/>
    </material>
    
    <!-- ros2_control -->
    <ros2_control name="GazeboSimSystem" type="system">
        <hardware>
            <plugin>gz_ros2_control/GazeboSimSystem</plugin>
        </hardware>
        <joint name="left_wheel_joint">
            <command_interface name="velocity">
                <param name="min">-10</param>
                <param name="max">10</param>
            </command_interface>
            <state_interface name="velocity"/>
            <state_interface name="position"/>
        </joint>
        <joint name="right_wheel_joint">
            <command_interface name="velocity">
                <param name="min">-10</param>
                <param name="max">10</param>
            </command_interface>
            <state_interface name="velocity"/>
            <state_interface name="position"/>
        </joint>
    </ros2_control>

    <!-- Links -->
    <link name="base_link">
        <inertial>
            <origin xyz="0 0 0.05" rpy="0 0 0"/>
            <mass value="1.0"/>
            <inertia ixx="0.008333" ixy="0.0" ixz="0.0"
                     iyy="0.011667" iyz="0.0"
                     izz="0.015833"/>
        </inertial>
        <visual>
            <geometry>
                <box size="0.3 0.2 0.1"/>
            </geometry>
            <material name="blue">
                <color rgba="0 0 1 1"/>
            </material>
        </visual>
        <collision>
            <geometry>
                <box size="0.3 0.2 0.1"/>
            </geometry>
        </collision>
    </link>

    <link name="left_wheel">
        <inertial>
            <origin xyz="0 0 0" rpy="1.5707 0 0"/>
            <mass value="0.1"/>
            <inertia ixx="0.000067083" ixy="0.0" ixz="0.0"
                     iyy="0.000067083" iyz="0.0"
                     izz="0.000125"/>
        </inertial>
        <visual>
            <geometry>
                <cylinder radius="0.05" length="0.02"/>
            </geometry>
            <material name="black">
                <color rgba="0 0 0 1"/>
            </material>
        </visual>
        <collision>
            <geometry>
                <cylinder radius="0.05" length="0.02"/>
            </geometry>
        </collision>
    </link>

    <link name="right_wheel">
        <inertial>
            <origin xyz="0 0 0" rpy="1.5707 0 0"/>
            <mass value="0.1"/>
            <inertia ixx="0.000067083" ixy="0.0" ixz="0.0"
                     iyy="0.000067083" iyz="0.0"
                     izz="0.000125"/>
        </inertial>
        <visual>
            <geometry>
                <cylinder radius="0.05" length="0.02"/>
            </geometry>
            <material name="black">
                <color rgba="0 0 0 1"/>
            </material>
        </visual>
        <collision>
            <geometry>
                <cylinder radius="0.05" length="0.02"/>
            </geometry>
        </collision>
    </link>

    <link name="caster_wheel">
        <inertial>
            <origin xyz="0 0 0" rpy="0 0 0"/>
            <mass value="0.05"/>
            <inertia ixx="0.000003125" ixy="0.0" ixz="0.0"
                     iyy="0.000003125" iyz="0.0"
                     izz="0.000003125"/>
        </inertial>
        <visual>
            <geometry>
                <sphere radius="0.025"/>
            </geometry>
            <material name="white">
                <color rgba="1 1 1 1"/>
            </material>
        </visual>
        <collision>
            <geometry>
                <sphere radius="0.025"/>
            </geometry>
        </collision>
    </link>

    <!-- Joints -->
    <joint name="left_wheel_joint" type="continuous">
        <parent link="base_link"/>
        <child link="left_wheel"/>
        <origin xyz="0 0.175 0" rpy="0 0 0"/>
        <axis xyz="0 1 0"/>
    </joint>

    <joint name="right_wheel_joint" type="continuous">
        <parent link="base_link"/>
        <child link="right_wheel"/>
        <origin xyz="0 -0.175 0" rpy="0 0 0"/>
        <axis xyz="0 1 0"/>
    </joint>

    <joint name="caster_wheel_joint" type="continuous">
        <parent link="base_link"/>
        <child link="caster_wheel"/>
        <origin xyz="0.15 0 -0.05" rpy="0 0 0"/>
        <axis xyz="0 0 1"/>
    </joint>
</robot>